Workbook

Sheet Explainer
B1: Tier 1 by Pos | C1: Tier 2 by Pos | D1: Tier 3 by Pos | F1: Hit | G1: Mid | H1: Miss
A2: QB | B2: Top 6 | C2: Top 12 | D2: Top 18 | F2: A Tier 1 Season or Multiple Tier 2 or better seasons | G2: A Tier 2 Season with a Tier 3 season or multiple Tier 3 seasons | H2: Never multiple Tier 3 seasons or better
A3: RB | B3: Top 12 | C3: Top 24 | D3: Top 36 | F3: " | G3: " | H3: "
A4: WR | B4: Top 12 | C4: Top 24 | D4: Top 36 | F4: " | G4: " | H4: "
A5: TE | B5: Top 3 | C5: Top 6 | D5: Top 12 | F5: " | G5: " | H5: "

Sheet PicksBySeason
B1: Player | C1: Position | D1: Pick | E1: Year | F1: Tier 1 Season | G1: Tier 2 Season | H1: Tier 3 Season | J1: Hit | K1: Mid | L1: Miss
A2: 1 | B2: Saquon Barkley | C2: RB | D2: 1.01 | E2: 2018 | F2: 4 | G2: 1 | H2: 1 | J2: 1
A3: 2 | B3: Baker Mayfield | C3: QB | D3: 1.02 | E3: 2018 | F3: 1 | G3: 1 | H3: 2 | J3: 1
A4: 3 | B4: Derrius Guice | C4: RB | D4: 1.03 | E4: 2018 | L4: 1
A5: 4 | B5: Nick Chubb | C5: RB | D5: 1.04 | E5: 2018 | F5: 3 | G5: 2 | J5: 1
A6: 5 | B6: Josh Rosen | C6: QB | D6: 1.05 | E6: 2018 | L6: 1
A7: 6 | B7: Sam Darnold | C7: QB | D7: 1.06 | E7: 2018 | G7: 1 | L7: 1
A8: 7 | B8: Lamar Jackson | C8: QB | D8: 1.07 | E8: 2018 | F8: 3 | G8: 1 | H8: 2 | J8: 1
A9: 8 | B9: Rashaad Penny | C9: RB | D9: 1.08 | E9: 2018 | L9: 1
A10: 9 | B10: Sony Michel | C10: RB | D10: 1.09 | E10: 2018 | G10: 1 | H10: 2 | K10: 1
A11: 10 | B11: Ronald Jones | C11: RB | D11: 1.1 | E11: 2018 | L11: 1
A12: 11 | B12: DJ Moore | C12: WR | D12: 1.11 | E12: 2018 | F12: 1 | G12: 3 | H12: 3 | J12: 1
A13: 12 | B13: Royce Freeman | C13: RB | D13: 1.12 | E13: 2018 | L13: 1
A14: 13 | B14: Calvin Ridley | C14: WR | D14: 2.01 | E14: 2018 | F14: 1 | G14: 3 | H14: 1 | J14: 1
A15: 14 | B15: Kerryon Johnson | C15: RB | D15: 2.02 | E15: 2018 | H15: 1 | L15: 1
A16: 15 | B16: Christian Kirk | C16: WR | D16: 2.03 | E16: 2018 | F16: 1 | H16: 1 | J16: 1
A17: 16 | B17: Courtland Sutton | C17: WR | D17: 2.04 | E17: 2018 | G17: 2 | H17: 1 | J17: 1
A18: 17 | B18: Josh Allen | C18: QB | D18: 2.05 | E18: 2018 | F18: 6 | J18: 1
A19: 18 | B19: James Washington | C19: WR | D19: 2.06 | E19: 2018 | L19: 1
A20: 19 | B20: Michael Gallup | C20: WR | D20: 2.07 | E20: 2018 | L20: 1
A21: 20 | B21: Anthony Miller | C21: WR | D21: 2.08 | E21: 2018 | L21: 1
A22: 21 | B22: Mike Gesicki | C22: TE | D22: 2.09 | E22: 2018 | H22: 3 | K22: 1
A23: 22 | B23: Dante Pettis | C23: WR | D23: 2.1 | E23: 2018 | L23: 1
A24: 23 | B24: Kalen Ballage | C24: RB | D24: 2.11 | E24: 2018 | L24: 1
A25: 24 | B25: Mason Rudolph | C25: QB | D25: 2.12 | E25: 2018 | L25: 1
A26: 25 | B26: Nyheim Hines | C26: RB | D26: 3.01 | E26: 2018 | G26: 1 | H26: 1 | K26: 1
A27: 26 | B27: Equanimeous St. Brown | C27: WR | D27: 3.02 | E27: 2018 | L27: 1
A28: 27 | B28: Dallas Goedert | C28: TE | D28: 3.03 | E28: 2018 | H28: 3 | K28: 1
A29: 28 | B29: Tre’Quan Smith | C29: WR | D29: 3.04 | E29: 2018 | L29: 1
A30: 29 | B30: DJ Chark | C30: WR | D30: 3.05 | E30: 2018 | G30: 1 | L30: 1
A31: 30 | B31: Antonio Callaway | C31: WR | D31: 3.06 | E31: 2018 | L31: 1
A32: 31 | B32: Kyle Lauletta | C32: QB | D32: 3.07 | E32: 2018 | L32: 1
A33: 32 | B33: Deon Cain | C33: WR | D33: 3.08 | E33: 2018 | L33: 1
A34: 33 | B34: Hayden Hurst | C34: TE | D34: 3.09 | E34: 2018 | L34: 1
A35: 34 | B35: DaeSean Hamilton | C35: WR | D35: 3.1 | E35: 2018 | L35: 1
A36: 35 | B36: Mark Andrews | C36: TE | D36: 3.11 | E36: 2018 | F36: 1 | G36: 4 | J36: 1
A37: 36 | B37: John Kelly | C37: RB | D37: 3.12 | E37: 2018 | L37: 1
A38: 37 | B38: Kyler Murray | C38: QB | D38: 1.01 | E38: 2019 | F38: 1 | G38: 3 | J38: 1
A39: 38 | B39: Josh Jacobs | C39: RB | D39: 1.02 | E39: 2019 | F39: 4 | G39: 1 | H39: 1 | J39: 1
A40: 39 | B40: Miles Sanders | C40: RB | D40: 1.03 | E40: 2019 | G40: 3 | J40: 1
...

Sheet Results
B1: Hit Rate | C1: Mid Rate | D1: Miss Rate
A2: 1.01 | B2: =(PicksBySeason!J2+PicksBySeason!J38+PicksBySeason!J74+PicksBySeason!J110+PicksBySeason!J146+PicksBySeason!J182)/6 -> 0.83333333 | C2: =(PicksBySeason!J2+PicksBySeason!J38+PicksBySeason!J74+PicksBySeason!J110+PicksBySeason!J146+PicksBySeason!J182+PicksBySeason!K2+PicksBySeason!K38+PicksBySeason!K74+PicksBySeason!K110+PicksBySeason!K146+PicksBySeason!K182)/6 -> 1 | D2: =100%-C2 -> 0
A3: Top 4 | B3: =Sum(PicksBySeason!J2:J5,PicksBySeason!J38:J41,PicksBySeason!J74:J77,PicksBySeason!J110:J113,PicksBySeason!J146:J149,PicksBySeason!J182:J185)/24 -> 0.70833333 | C3: =Sum(PicksBySeason!J2:J5,PicksBySeason!J38:J41,PicksBySeason!J74:J77,PicksBySeason!J110:J113,PicksBySeason!J146:J149,PicksBySeason!J182:J185,PicksBySeason!K2:K5,PicksBySeason!K38:K41,PicksBySeason!K74:K77,PicksBySeason!K110:K113,PicksBySeason!K146:K149,PicksBySeason!K182:K185)/24 -> 0.83333333 | D3: =100%-C3 -> 0.16666667
A4: 1.05 -1.08 | B4: =Sum(PicksBySeason!J6:J9,PicksBySeason!J42:J45,PicksBySeason!J78:J81,PicksBySeason!J114:J117,PicksBySeason!J150:J153,PicksBySeason!J186:J189)/24 -> 0.375 | C4: =Sum(PicksBySeason!J6:J9,PicksBySeason!J42:J45,PicksBySeason!J78:J81,PicksBySeason!J114:J117,PicksBySeason!J150:J153,PicksBySeason!J186:J189,PicksBySeason!K6:K9,PicksBySeason!K42:K45,PicksBySeason!K78:K81,PicksBySeason!K114:K117,PicksBySeason!K150:K153,PicksBySeason!K186:K189)/24 -> 0.41666667 | D4: =100%-C4 -> 0.58333333
A5: 1.09 - 1.12 | B5: =Sum(PicksBySeason!J10:J13,PicksBySeason!J46:J49,PicksBySeason!J82:J85,PicksBySeason!J118:J121,PicksBySeason!J154:J157,PicksBySeason!J190:J193)/24 -> 0.45833333 | C5: =Sum(PicksBySeason!J10:J13,PicksBySeason!J46:J49,PicksBySeason!J82:J85,PicksBySeason!J118:J121,PicksBySeason!J154:J157,PicksBySeason!J190:J193,PicksBySeason!K10:K13,PicksBySeason!K46:K49,PicksBySeason!K82:K85,PicksBySeason!K118:K121,PicksBySeason!K154:K157,PicksBySeason!K190:K193)/24 -> 0.625 | D5: =100%-C5 -> 0.375
A6: Top Half of 2nd | B6: =Sum(PicksBySeason!J14:J19,PicksBySeason!J50:J55,PicksBySeason!J86:J91,PicksBySeason!J122:J127,PicksBySeason!J158:J163,PicksBySeason!J194:J199)/36 -> 0.22222222 | C6: =Sum(PicksBySeason!J14:J19,PicksBySeason!J50:J55,PicksBySeason!J86:J91,PicksBySeason!J122:J127,PicksBySeason!J158:J163,PicksBySeason!J194:J199,PicksBySeason!K14:K19,PicksBySeason!K50:K55,PicksBySeason!K86:K91,PicksBySeason!K122:K127,PicksBySeason!K158:K163,PicksBySeason!K194:K199)/36 -> 0.30555556 | D6: =100%-C6 -> 0.69444444
A7: Bottom Half of 2nd | B7: =Sum(PicksBySeason!J20:J25,PicksBySeason!J56:J61,PicksBySeason!J92:J97,PicksBySeason!J128:J133,PicksBySeason!J164:J169,PicksBySeason!J200:J205)/36 -> 0.19444444 | C7: =Sum(PicksBySeason!J20:J25,PicksBySeason!J56:J61,PicksBySeason!J92:J97,PicksBySeason!J128:J133,PicksBySeason!J164:J169,PicksBySeason!J200:J205,PicksBySeason!K20:K25,PicksBySeason!K56:K61,PicksBySeason!K92:K97,PicksBySeason!K128:K133,PicksBySeason!K164:K169,PicksBySeason!K200:K205)/36 -> 0.33333333 | D7: =100%-C7 -> 0.66666667
A8: 3rd Rd | B8: =Sum(PicksBySeason!J26:J37,PicksBySeason!J62:J73,PicksBySeason!J98:J109,PicksBySeason!J134:J145,PicksBySeason!J170:J181,PicksBySeason!J206:J217)/72 -> 0.083333333 | C8: =Sum(PicksBySeason!J26:J37,PicksBySeason!J62:J73,PicksBySeason!J98:J109,PicksBySeason!J134:J145,PicksBySeason!J170:J181,PicksBySeason!J206:J217,PicksBySeason!K26:K37,PicksBySeason!K62:K73,PicksBySeason!K98:K109,PicksBySeason!K134:K145,PicksBySeason!K170:K181,PicksBySeason!K206:K217)/72 -> 0.13888889 | D8: =100%-C8 -> 0.86111111
A17: Players that still could realistically be "hits"
A18: 1.01 | B18: Trevor Lawrence
A19: Top 4 | B19: Tua Tagovailoa
A20: 1.05 -1.08 | B20: Kyle Pitts | C20: Chis Olave | D20: George Pickens
A21: 1.09 - 1.12 | B21: Jovante Williams | C21: Jameson Williams | D21: Zay Flowers
A22: Top Half of 2nd | B22: Pat Freiermuth | C22: Brian Robinson Jr
A23: Bottom Half of 2nd
A24: 3rd Rd | B24: Tucker Kraft
